Workbook
Name UPDATE: 'Data Sheet'!$E$1

Sheet Profit & Loss
A1: ='Data Sheet'!B1 -> DIVIS LABORATORIES LTD
A3: Narration | B3: ='Data Sheet'!J16 -> 45382 | C3: ='Data Sheet'!K16 -> 45747 | D3: Trailing
A4: Sales | B4: ='Data Sheet'!J17 -> 7665 | C4: ='Data Sheet'!K17 -> 9198 | D4: =SUM(Quarters!H4:K4) -> 9850
A5: Expenses | B5: =SUM('Data Sheet'!J18,'Data Sheet'!J20:J24, -1*'Data Sheet'!J19) -> 5486 | C5: =SUM('Data Sheet'!K18,'Data Sheet'!K20:K24, -1*'Data Sheet'!K19) -> 6214 | D5: =SUM(Quarters!H5:K5) -> 6584
A6: Operating Profit | B6: =B4-B5 -> 2179 | C6: =C4-C5 -> 2984 | D6: =SUM(Quarters!H6:K6) -> 3266
A7: Other Income | B7: ='Data Sheet'!J25 -> 333 | C7: ='Data Sheet'!K25 -> 348 | D7: =SUM(Quarters!H7:K7) -> 434
A8: Depreciation | B8: ='Data Sheet'!J26 -> 376 | C8: ='Data Sheet'!K26 -> 401 | D8: =SUM(Quarters!H8:K8) -> 431
A9: Interest | B9: ='Data Sheet'!J27 -> 4 | C9: ='Data Sheet'!K27 -> 2 | D9: =SUM(Quarters!H9:K9) -> 11
A10: Profit before tax | B10: ='Data Sheet'!J28 -> 2132 | C10: ='Data Sheet'!K28 -> 2929 | D10: =SUM(Quarters!H10:K10) -> 3258
A11: Tax | B11: ='Data Sheet'!J29 -> 556 | C11: ='Data Sheet'!K29 -> 720 | D11: =SUM(Quarters!H11:K11) -> 744
A12: Net profit | B12: ='Data Sheet'!J30 -> 1576 | C12: ='Data Sheet'!K30 -> 2209 | D12: =SUM(Quarters!H12:K12) -> 2514
A13: EPS | B13: =IF('Data Sheet'!J93>0,B12/'Data Sheet'!J93,0) -> 59.359699 | C13: =IF('Data Sheet'!K93>0,C12/'Data Sheet'!K93,0) -> 83.201507 | D13: =IF('Data Sheet'!$B6>0,'Profit & Loss'!D12/'Data Sheet'!$B6,0) -> 94.70047
A14: Price to earning | B14: =IF(B15>0,B15/B13,"") -> 58.041063 | C14: =IF(C15>0,C15/C13,"") -> 69.415209 | D14: =IF(D13>0,D15/D13,0) -> 69.867657
A15: Price | B15: ='Data Sheet'!J90 -> 3445.3 | C15: ='Data Sheet'!K90 -> 5775.45 | D15: ='Data Sheet'!B8 -> 6616.5
A17: RATIOS:
A18: Dividend Payout | B18: =IF('Data Sheet'!J30>0, 'Data Sheet'!J31/'Data Sheet'!J30, 0) -> 0.50444162 | C18: =IF('Data Sheet'!K30>0, 'Data Sheet'!K31/'Data Sheet'!K30, 0) -> 0.35989135
A19: OPM | B19: =IF(B6>0,B6/B4,0) -> 0.28427919 | C19: =IF(C6>0,C6/C4,0) -> 0.32441835 | D19: =IF(D6>0,D6/D4,0) -> 0.3315736

Sheet Quarters
A1: ='Profit & Loss'!A1 -> DIVIS LABORATORIES LTD | E1: =UPDATE | J1: SCREENER.IN
A3: Narration | B3: ='Data Sheet'!B41 -> 45107 | C3: ='Data Sheet'!C41 -> 45199 | D3: ='Data Sheet'!D41 -> 45291 | E3: ='Data Sheet'!E41 -> 45382 | F3: ='Data Sheet'!F41 -> 45473 | G3: ='Data Sheet'!G41 -> 45565 | H3: ='Data Sheet'!H41 -> 45657 | I3: ='Data Sheet'!I41 -> 45747 | ... K3: ='Data Sheet'!K41 -> 45930
A4: Sales | B4: ='Data Sheet'!B42 -> 1730 | C4: ='Data Sheet'!C42 -> 1868 | D4: ='Data Sheet'!D42 -> 1808 | E4: ='Data Sheet'!E42 -> 2259 | F4: ='Data Sheet'!F42 -> 2063 | G4: ='Data Sheet'!G42 -> 2302 | H4: ='Data Sheet'!H42 -> 2297 | I4: ='Data Sheet'!I42 -> 2536 | ... K4: ='Data Sheet'!K42 -> 2660
A5: Expenses | B5: ='Data Sheet'!B43 -> 1239 | C5: ='Data Sheet'!C43 -> 1394 | D5: ='Data Sheet'!D43 -> 1317 | E5: ='Data Sheet'!E43 -> 1542 | F5: ='Data Sheet'!F43 -> 1442 | G5: ='Data Sheet'!G43 -> 1573 | H5: ='Data Sheet'!H43 -> 1550 | I5: ='Data Sheet'!I43 -> 1655 | ... K5: ='Data Sheet'!K43 -> 1765
A6: Operating Profit | B6: ='Data Sheet'!B50 -> 491 | C6: ='Data Sheet'!C50 -> 474 | D6: ='Data Sheet'!D50 -> 491 | E6: ='Data Sheet'!E50 -> 717 | F6: ='Data Sheet'!F50 -> 621 | G6: ='Data Sheet'!G50 -> 729 | H6: ='Data Sheet'!H50 -> 747 | I6: ='Data Sheet'!I50 -> 881 | ... K6: ='Data Sheet'!K50 -> 895
A7: Other Income | B7: ='Data Sheet'!B44 -> 80 | C7: ='Data Sheet'!C44 -> 85 | D7: ='Data Sheet'!D44 -> 94 | E7: ='Data Sheet'!E44 -> 79 | F7: ='Data Sheet'!F44 -> 79 | G7: ='Data Sheet'!G44 -> 105 | H7: ='Data Sheet'!H44 -> 82 | I7: ='Data Sheet'!I44 -> 87 | ... K7: ='Data Sheet'!K44 -> 146
A8: Depreciation | B8: ='Data Sheet'!B45 -> 93 | C8: ='Data Sheet'!C45 -> 94 | D8: ='Data Sheet'!D45 -> 95 | E8: ='Data Sheet'!E45 -> 94 | F8: ='Data Sheet'!F45 -> 97 | G8: ='Data Sheet'!G45 -> 98 | H8: ='Data Sheet'!H45 -> 99 | I8: ='Data Sheet'!I45 -> 107 | ... K8: ='Data Sheet'!K45 -> 113
A9: Interest | B9: ='Data Sheet'!B46 -> 0 | C9: ='Data Sheet'!C46 -> 1 | D9: ='Data Sheet'!D46 -> 0 | E9: ='Data Sheet'!E46 -> 2 | F9: ='Data Sheet'!F46 -> 0 | G9: ='Data Sheet'!G46 -> 1 | H9: ='Data Sheet'!H46 -> 0 | I9: ='Data Sheet'!I46 -> 0 | ... K9: ='Data Sheet'!K46 -> 8
A10: Profit before tax | B10: ='Data Sheet'!B47 -> 478 | C10: ='Data Sheet'!C47 -> 464 | D10: ='Data Sheet'!D47 -> 490 | E10: ='Data Sheet'!E47 -> 700 | F10: ='Data Sheet'!F47 -> 603 | G10: ='Data Sheet'!G47 -> 735 | H10: ='Data Sheet'!H47 -> 730 | I10: ='Data Sheet'!I47 -> 861 | ... K10: ='Data Sheet'!K47 -> 920
A11: Tax | B11: ='Data Sheet'!B48 -> 133 | C11: ='Data Sheet'!C48 -> 122 | D11: ='Data Sheet'!D48 -> 132 | E11: ='Data Sheet'!E48 -> 169 | F11: ='Data Sheet'!F48 -> 173 | G11: ='Data Sheet'!G48 -> 217 | H11: ='Data Sheet'!H48 -> 136 | I11: ='Data Sheet'!I48 -> 194 | ... K11: ='Data Sheet'!K48 -> 224
A12: Net profit | B12: ='Data Sheet'!B49 -> 345 | C12: ='Data Sheet'!C49 -> 342 | D12: ='Data Sheet'!D49 -> 358 | E12: ='Data Sheet'!E49 -> 531 | F12: ='Data Sheet'!F49 -> 430 | G12: ='Data Sheet'!G49 -> 518 | H12: ='Data Sheet'!H49 -> 594 | I12: ='Data Sheet'!I49 -> 667 | ... K12: ='Data Sheet'!K49 -> 696
A14: OPM | B14: =IF(B4>0,B6/B4,"") -> 0.28381503 | C14: =IF(C4>0,C6/C4,"") -> 0.25374732 | D14: =IF(D4>0,D6/D4,"") -> 0.2715708 | E14: =IF(E4>0,E6/E4,"") -> 0.31739708 | F14: =IF(F4>0,F6/F4,"") -> 0.30101794 | G14: =IF(G4>0,G6/G4,"") -> 0.31668115 | H14: =IF(H4>0,H6/H4,"") -> 0.32520679 | I14: =IF(I4>0,I6/I4,"") -> 0.34739748 | ... K14: =IF(K4>0,K6/K4,"") -> 0.33646617

Sheet Balance Sheet
A1: ='Profit & Loss'!A1 -> DIVIS LABORATORIES LTD | E1: SCREENER.IN
A3: Narration | B3: ='Data Sheet'!B56 -> 42460 | C3: ='Data Sheet'!C56 -> 42825 | D3: ='Data Sheet'!D56 -> 43190 | E3: ='Data Sheet'!J56 -> 45382 | F3: ='Data Sheet'!K56 -> 45747
A4: Equity Share Capital | B4: ='Data Sheet'!B57 -> 53.09 | C4: ='Data Sheet'!C57 -> 53.09 | D4: ='Data Sheet'!D57 -> 53.09 | E4: ='Data Sheet'!J57 -> 53 | F4: ='Data Sheet'!K57 -> 53
A5: Reserves | B5: ='Data Sheet'!B58 -> 4303.95 | C5: ='Data Sheet'!C58 -> 5355.82 | D5: ='Data Sheet'!D58 -> 5906.56 | E5: ='Data Sheet'!J58 -> 13431 | F5: ='Data Sheet'!K58 -> 14842
A6: Borrowings | B6: ='Data Sheet'!B59 -> 42.47 | C6: ='Data Sheet'!C59 -> 35.74 | D6: ='Data Sheet'!D59 -> 63.11 | E6: ='Data Sheet'!J59 -> 0 | F6: ='Data Sheet'!K59 -> 2
A7: Other Liabilities | B7: ='Data Sheet'!B60 -> 565.98 | C7: ='Data Sheet'!C60 -> 765.43 | D7: ='Data Sheet'!D60 -> 785.02 | E7: ='Data Sheet'!J60 -> 1878 | F7: ='Data Sheet'!K60 -> 1927
A8: Total | B8: ='Data Sheet'!B61 -> 4965.49 | C8: ='Data Sheet'!C61 -> 6210.08 | D8: ='Data Sheet'!D61 -> 6807.78 | E8: ='Data Sheet'!J61 -> 15362 | F8: ='Data Sheet'!K61 -> 16824
A10: Net Block | B10: ='Data Sheet'!B62 -> 1438.64 | C10: ='Data Sheet'!C62 -> 1558.95 | D10: ='Data Sheet'!D62 -> 1995.88 | E10: ='Data Sheet'!J62 -> 4737 | F10: ='Data Sheet'!K62 -> 5440
A11: Capital Work in Progress | B11: ='Data Sheet'!B63 -> 263.91 | C11: ='Data Sheet'!C63 -> 443.57 | D11: ='Data Sheet'!D63 -> 119.76 | E11: ='Data Sheet'!J63 -> 778 | F11: ='Data Sheet'!K63 -> 1022
A12: Investments | B12: ='Data Sheet'!B64 -> 813.04 | C12: ='Data Sheet'!C64 -> 1639.09 | D12: ='Data Sheet'!D64 -> 1896.66 | E12: ='Data Sheet'!J64 -> 89 | F12: ='Data Sheet'!K64 -> 72
A13: Other Assets | B13: ='Data Sheet'!B65 -> 2449.9 | C13: ='Data Sheet'!C65 -> 2568.47 | D13: ='Data Sheet'!D65 -> 2795.48 | E13: ='Data Sheet'!J65 -> 9758 | F13: ='Data Sheet'!K65 -> 10290
A14: Total | B14: ='Data Sheet'!B66 -> 4965.49 | C14: ='Data Sheet'!C66 -> 6210.08 | D14: ='Data Sheet'!D66 -> 6807.78 | E14: ='Data Sheet'!J66 -> 15362 | F14: ='Data Sheet'!K66 -> 16824
A16: Working Capital | B16: =B13-B7 -> 1883.92 | C16: =C13-C7 -> 1803.04 | D16: =D13-D7 -> 2010.46 | E16: =E13-E7 -> 7880 | F16: =F13-F7 -> 8363
A17: Debtors | B17: ='Data Sheet'!B67 -> 966.12 | C17: ='Data Sheet'!C67 -> 1002.89 | D17: ='Data Sheet'!D67 -> 1112.11 | E17: ='Data Sheet'!J67 -> 2273 | F17: ='Data Sheet'!K67 -> 2855
A18: Inventory | B18: ='Data Sheet'!B68 -> 1162.89 | C18: ='Data Sheet'!C68 -> 1255.76 | D18: ='Data Sheet'!D68 -> 1281.39 | E18: ='Data Sheet'!J68 -> 2985 | F18: ='Data Sheet'!K68 -> 3033
A20: Debtor Days | B20: =IF('Profit & Loss'!#REF!>0,'Balance Sheet'!B17/('Profit & Loss'!#REF!/365),0) -> #REF! | C20: =IF('Profit & Loss'!#REF!>0,'Balance Sheet'!C17/('Profit & Loss'!#REF!/365),0) -> #REF! | D20: =IF('Profit & Loss'!#REF!>0,'Balance Sheet'!D17/('Profit & Loss'!#REF!/365),0) -> #REF! | E20: =IF('Profit & Loss'!B4>0,'Balance Sheet'!E17/('Profit & Loss'!B4/365),0) -> 108.2381 | F20: =IF('Profit & Loss'!C4>0,'Balance Sheet'!F17/('Profit & Loss'!C4/365),0) -> 113.29365
A21: Inventory Turnover | B21: =IF('Balance Sheet'!B18>0,'Profit & Loss'!#REF!/'Balance Sheet'!B18,0) -> #REF! | C21: =IF('Balance Sheet'!C18>0,'Profit & Loss'!#REF!/'Balance Sheet'!C18,0) -> #REF! | D21: =IF('Balance Sheet'!D18>0,'Profit & Loss'!#REF!/'Balance Sheet'!D18,0) -> #REF! | E21: =IF('Balance Sheet'!E18>0,'Profit & Loss'!B4/'Balance Sheet'!E18,0) -> 2.5678392 | F21: =IF('Balance Sheet'!F18>0,'Profit & Loss'!C4/'Balance Sheet'!F18,0) -> 3.0326409
A23: Return on Equity | B23: =IF(SUM('Balance Sheet'!B4:B5)>0,'Profit & Loss'!#REF!/SUM('Balance Sheet'!B4:B5),"") -> #REF! | C23: =IF(SUM('Balance Sheet'!C4:C5)>0,'Profit & Loss'!#REF!/SUM('Balance Sheet'!C4:C5),"") -> #REF! | D23: =IF(SUM('Balance Sheet'!D4:D5)>0,'Profit & Loss'!#REF!/SUM('Balance Sheet'!D4:D5),"") -> #REF! | E23: =IF(SUM('Balance Sheet'!E4:E5)>0,'Profit & Loss'!B12/SUM('Balance Sheet'!E4:E5),"") -> 0.11687926 | F23: =IF(SUM('Balance Sheet'!F4:F5)>0,'Profit & Loss'!C12/SUM('Balance Sheet'!F4:F5),"") -> 0.1483048
A24: Return on Capital Emp | C24: =IF((B4+B5+B6+C4+C5+C6)>0,('Profit & Loss'!#REF!+'Profit & Loss'!#REF!)*2/(B4+B5+B6+C4+C5+C6),"") -> #REF! | D24: =IF((C4+C5+C6+D4+D5+D6)>0,('Profit & Loss'!#REF!+'Profit & Loss'!#REF!)*2/(C4+C5+C6+D4+D5+D6),"") -> #REF! | E24: =IF((#REF!+#REF!+#REF!+E4+E5+E6)>0,('Profit & Loss'!B10+'Profit & Loss'!B9)*2/(#REF!+#REF!+#REF!+E4+E5+E6),"") -> #REF! | F24: =IF((E4+E5+E6+F4+F5+F6)>0,('Profit & Loss'!C10+'Profit & Loss'!C9)*2/(E4+E5+E6+F4+F5+F6),"") -> 0.20654663

Sheet Cash Flow
A1: ='Balance Sheet'!A1 -> DIVIS LABORATORIES LTD | E1: SCREENER.IN
A3: Narration | B3: ='Data Sheet'!B81 -> 42460 | C3: ='Data Sheet'!C81 -> 42825 | D3: ='Data Sheet'!D81 -> 43190 | E3: ='Data Sheet'!J81 -> 45382 | F3: ='Data Sheet'!K81 -> 45747
A4: Cash from Operating Activity | B4: ='Data Sheet'!B82 -> 1036.34 | C4: ='Data Sheet'!C82 -> 1149.11 | D4: ='Data Sheet'!D82 -> 764.72 | E4: ='Data Sheet'!J82 -> 1266 | F4: ='Data Sheet'!K82 -> 1650
A5: Cash from Investing Activity | B5: ='Data Sheet'!B83 -> -411.16 | C5: ='Data Sheet'!C83 -> -1137.41 | D5: ='Data Sheet'!D83 -> -475.89 | E5: ='Data Sheet'!J83 -> -268 | F5: ='Data Sheet'!K83 -> -803
A6: Cash from Financing Activity | B6: ='Data Sheet'!B84 -> -630.34 | C6: ='Data Sheet'!C84 -> 3.27 | D6: ='Data Sheet'!D84 -> -314.17 | E6: ='Data Sheet'!J84 -> -798 | F6: ='Data Sheet'!K84 -> -797
A7: Net Cash Flow | B7: ='Data Sheet'!B85 -> -5.17 | C7: ='Data Sheet'!C85 -> 14.97 | D7: ='Data Sheet'!D85 -> -25.34 | E7: ='Data Sheet'!J85 -> 200 | F7: ='Data Sheet'!K85 -> 50

Sheet Customization
A1: How to use it?
A3: You can customize this workbook as you want.
B4: You can add custom formating, add conditional formating, add your own formulas… do ANYTHING.
B5: Please don't edit the "Data Sheet" only.
A7: After customization, you can upload this back on Screener.
B8: Upload on: | C8: https://www.screener.in/excel/
A10: Download your customized workbooks now onwards.
B11: Now whenever you will "Export to excel" from Screener, it will export your customized file.
A14: TESTING:
B15: This is a testing feature currently.
B16: You can report any formula errors on the worksheet at: support@screener.in

Sheet Data Sheet
A1: COMPANY NAME | B1: DIVIS LABORATORIES LTD | E1: =IF(B2<>B3, "A NEW VERSION OF THE WORKSHEET IS AVAILABLE", "")
A2: LATEST VERSION | B2: 2.1 | E2: PLEASE DO NOT MAKE ANY CHANGES TO THIS SHEET
A3: CURRENT VERSION | B3: 2.1
A5: META
A6: Number of shares | B6: =IF(B9>0, B9/B8, 0) -> 26.546859
A7: Face Value | B7: 2
A8: Current Price | B8: 6616.5
A9: Market Capitalization | B9: 175647.29
A15: PROFIT & LOSS
A16: Report Date | B16: 42460 | C16: 42825 | D16: 43190 | E16: 43555 | F16: 43921 | G16: 44286 | H16: 44651 | I16: 45016 | J16: 45382 | K16: 45747
A17: Sales | B17: 3720.09 | C17: 4023.85 | D17: 3815.94 | E17: 4879.66 | F17: 5310.57 | G17: 6798.61 | H17: 8879.82 | I17: 7625 | J17: 7665 | K17: 9198
A18: Raw Material Cost | B18: 1472.43 | C18: 1595.93 | D18: 1524.28 | E18: 2120.64 | F18: 2223.95 | G18: 2416.47 | H18: 3499.18 | I18: 3035 | J18: 3270 | K18: 3827
A19: Change in Inventory | B19: -22.03 | C19: 21.61 | D19: 19.38 | E19: 244.22 | F19: 94.1 | G19: 100 | H19: 449.99 | I19: -50 | J19: 127 | K19: 83
A20: Power and Fuel | B20: 181.99 | C20: 198.8 | D20: 228.73 | E20: 248.78 | F20: 280.73 | G20: 319.15 | H20: 390.05 | I20: 496 | J20: 477 | K20: 465
A21: Other Mfr. Exp | B21: 133.02 | C21: 108.78 | D21: 158.57 | E21: 138.96 | F21: 184.36 | G21: 202.29 | H21: 255.38 | I21: 285 | J21: 299 | K21: 276
A22: Employee Cost | B22: 353.16 | C22: 490.49 | D22: 446.66 | E22: 531.23 | F22: 609.67 | G22: 810.77 | H22: 928.72 | I22: 955 | J22: 1069 | K22: 1212
A23: Selling and admin | B23: 86.31 | C23: 137.48 | D23: 201.6 | E23: 171.33 | F23: 221.55 | G23: 290.44 | H23: 337.99 | I23: 400 | J23: 365 | K23: 447
A24: Other Expenses | B24: 65.49 | C24: 72.61 | D24: 17.61 | E24: 61.48 | F24: 64.75 | G24: 31.73 | H24: 38.9 | I24: 54 | J24: 133 | K24: 70
A25: Other Income | B25: 91.68 | C25: 73.45 | D25: 106.22 | E25: 155.19 | F25: 186.61 | G25: 56.57 | H25: 109.21 | I25: 348 | J25: 333 | K25: 348
A26: Depreciation | B26: 118.1 | C26: 123.26 | D26: 142.42 | E26: 168.81 | F26: 185.95 | G26: 254.65 | H26: 310.55 | I26: 342 | J26: 376 | K26: 401
A27: Interest | B27: 3.95 | C27: 3.33 | D27: 2.31 | E27: 4.61 | F27: 7.03 | G27: 1.81 | H27: 1.73 | I27: 2 | J27: 4 | K27: 2
... A31: Dividend Amount | B31: 265.45 | C31: 265.45 | D31: 265.45 | E31: 424.72 | F31: 424.72 | G31: 530.9 | H31: 796.35 | I31: 795 | J31: 795 | K31: 795
A40: Quarters
A41: Report Date | B41: 45107 | C41: 45199 | D41: 45291 | E41: 45382 | F41: 45473 | G41: 45565 | H41: 45657 | I41: 45747 | J41: 45838 | K41: 45930
A42: Sales | B42: 1730 | C42: 1868 | D42: 1808 | E42: 2259 | F42: 2063 | G42: 2302 | H42: 2297 | I42: 2536 | J42: 2357 | K42: 2660
A43: Expenses | B43: 1239 | C43: 1394 | D43: 1317 | E43: 1542 | F43: 1442 | G43: 1573 | H43: 1550 | I43: 1655 | J43: 1614 | K43: 1765
A44: Other Income | B44: 80 | C44: 85 | D44: 94 | E44: 79 | F44: 79 | G44: 105 | H44: 82 | I44: 87 | J44: 119 | K44: 146
A45: Depreciation | B45: 93 | C45: 94 | D45: 95 | E45: 94 | F45: 97 | G45: 98 | H45: 99 | I45: 107 | J45: 112 | K45: 113
A46: Interest | C46: 1 | E46: 2 | G46: 1 | J46: 3 | K46: 8
A47: Profit before tax | B47: 478 | C47: 464 | D47: 490 | E47: 700 | F47: 603 | G47: 735 | H47: 730 | I47: 861 | J47: 747 | K47: 920
A48: Tax | B48: 133 | C48: 122 | D48: 132 | E48: 169 | F48: 173 | G48: 217 | H48: 136 | I48: 194 | J48: 190 | K48: 224
A49: Net profit | B49: 345 | C49: 342 | D49: 358 | E49: 531 | F49: 430 | G49: 518 | H49: 594 | I49: 667 | J49: 557 | K49: 696
A50: Operating Profit | B50: 491 | C50: 474 | D50: 491 | E50: 717 | F50: 621 | G50: 729 | H50: 747 | I50: 881 | J50: 743 | K50: 895
A55: BALANCE SHEET
A56: Report Date | B56: 42460 | C56: 42825 | D56: 43190 | E56: 43555 | F56: 43921 | G56: 44286 | H56: 44651 | I56: 45016 | J56: 45382 | K56: 45747
A57: Equity Share Capital | B57: 53.09 | C57: 53.09 | D57: 53.09 | E57: 53.09 | F57: 53.09 | G57: 53.09 | H57: 53.09 | I57: 53 | J57: 53 | K57: 53
A58: Reserves | B58: 4303.95 | C58: 5355.82 | D58: 5906.56 | E58: 6920.22 | F58: 7263.6 | G58: 9218.48 | H58: 11638.26 | I58: 12652 | J58: 13431 | K58: 14842
A59: Borrowings | B59: 42.47 | C59: 35.74 | D59: 63.11 | E59: 105.6 | F59: 33.63 | G59: 0.35 | K59: 2
A60: Other Liabilities | B60: 565.98 | C60: 765.43 | D60: 785.02 | E60: 961.27 | F60: 1163.79 | G60: 1451.85 | H60: 1616.51 | I60: 1647 | J60: 1878 | K60: 1927
A61: Total | B61: 4965.49 | C61: 6210.08 | D61: 6807.78 | E61: 8040.18 | F61: 8514.11 | G61: 10723.77 | H61: 13307.86 | I61: 14352 | J61: 15362 | K61: 16824
...
